Workbook

Sheet Summary
A2: University building decarbonisation
A4: 20 fictional buildings. Annual steady-state analysis in 2026 prices. Start with Assumptions, then Buildings.
A6: Portfolio metric | B6: Value | C6: Unit
A7: Buildings | B7: =COUNTA(Buildings!A7:A26) -> 20 | C7: count
A8: Capital investment | B8: =CAPEX!S28 -> 21907738 | C8: £
A9: Baseline OPEX | B9: =Energy!AB28 -> 6771180 | C9: £/yr
A10: Proposed OPEX | B10: =Energy!AC28 -> 6447576.8 | C10: £/yr
A11: Annual OPEX saving | B11: =Energy!AD28 -> 323603.16 | C11: £/yr
A12: Baseline emissions | B12: =Energy!S28 -> 6502.162 | C12: tCO2e/yr
A13: Proposed emissions | B13: =Energy!T28 -> 3355.513 | C13: tCO2e/yr
A14: Emissions saved | B14: =Energy!U28 -> 3146.649 | C14: tCO2e/yr
A15: Emissions reduction | B15: =Energy!V28 -> 0.48393888 | C15: %
A16: Heat-pump units | B16: =CAPEX!F28 -> 78 | C16: count
A17: Additional peak electricity | B17: =CAPEX!I28 -> 3120 | C17: kWe
A18: Sum of site shortfalls | B18: =CAPEX!K28 -> 2080 | C18: kWe
A19: Portfolio simple payback | B19: =CAPEX!U28 -> 67.699393 | C19: years
A23: Cluster | B23: CAPEX £ | C23: OPEX saving £/yr | D23: Emissions saved t/yr | E23: HP units | F23: Additional peak kWe | G23: Site shortfalls kWe
A24: North | B24: =SUMIFS(CAPEX!$S$7:$S$26,CAPEX!$C$7:$C$26,$A24) -> 4932614.4 | C24: =SUMIFS(Energy!$AD$7:$AD$26,Energy!$C$7:$C$26,$A24) -> 57551.298 | D24: =SUMIFS(Energy!$U$7:$U$26,Energy!$C$7:$C$26,$A24) -> 679.80432 | E24: =SUMIFS(CAPEX!$F$7:$F$26,CAPEX!$C$7:$C$26,$A24) -> 19 | F24: =SUMIFS(CAPEX!$I$7:$I$26,CAPEX!$C$7:$C$26,$A24) -> 760 | G24: =SUMIFS(CAPEX!$K$7:$K$26,CAPEX!$C$7:$C$26,$A24) -> 500
A25: Central | B25: =SUMIFS(CAPEX!$S$7:$S$26,CAPEX!$C$7:$C$26,$A25) -> 6210355.2 | C25: =SUMIFS(Energy!$AD$7:$AD$26,Energy!$C$7:$C$26,$A25) -> 90701.046 | D25: =SUMIFS(Energy!$U$7:$U$26,Energy!$C$7:$C$26,$A25) -> 911.73249 | E25: =SUMIFS(CAPEX!$F$7:$F$26,CAPEX!$C$7:$C$26,$A25) -> 22 | F25: =SUMIFS(CAPEX!$I$7:$I$26,CAPEX!$C$7:$C$26,$A25) -> 880 | G25: =SUMIFS(CAPEX!$K$7:$K$26,CAPEX!$C$7:$C$26,$A25) -> 620
A26: South | B26: =SUMIFS(CAPEX!$S$7:$S$26,CAPEX!$C$7:$C$26,$A26) -> 4997395.2 | C26: =SUMIFS(Energy!$AD$7:$AD$26,Energy!$C$7:$C$26,$A26) -> 85382.431 | D26: =SUMIFS(Energy!$U$7:$U$26,Energy!$C$7:$C$26,$A26) -> 753.7847 | E26: =SUMIFS(CAPEX!$F$7:$F$26,CAPEX!$C$7:$C$26,$A26) -> 17 | F26: =SUMIFS(CAPEX!$I$7:$I$26,CAPEX!$C$7:$C$26,$A26) -> 680 | G26: =SUMIFS(CAPEX!$K$7:$K$26,CAPEX!$C$7:$C$26,$A26) -> 420
A27: West | B27: =SUMIFS(CAPEX!$S$7:$S$26,CAPEX!$C$7:$C$26,$A27) -> 5767372.8 | C27: =SUMIFS(Energy!$AD$7:$AD$26,Energy!$C$7:$C$26,$A27) -> 89968.388 | D27: =SUMIFS(Energy!$U$7:$U$26,Energy!$C$7:$C$26,$A27) -> 801.32746 | E27: =SUMIFS(CAPEX!$F$7:$F$26,CAPEX!$C$7:$C$26,$A27) -> 20 | F27: =SUMIFS(CAPEX!$I$7:$I$26,CAPEX!$C$7:$C$26,$A27) -> 800 | G27: =SUMIFS(CAPEX!$K$7:$K$26,CAPEX!$C$7:$C$26,$A27) -> 540
A30: Energy totals
A31: Metric | B31: Baseline kWh/yr | C31: Proposed kWh/yr
A32: Useful heat | B32: =Energy!G28 -> 15921600 | C32: =Energy!I28 -> 13009760
A33: Gas purchased | B33: =Energy!D28 -> 19000000 | C33: 0
A34: Grid electricity | B34: =Energy!E28 -> 23200000 | C34: =Energy!P28 -> 25622427
A35: Heat-pump electricity | B35: 0 | C35: =Energy!K28 -> 4069651.9
A36: PV self-used | B36: 0 | C36: =Energy!N28 -> 1647225
A39: Useful heat = gas × boiler efficiency. Heat-pump electricity = reduced useful heat ÷ seasonal COP.
A40: CAPEX = upfront investment. OPEX = annual energy bills plus modelled plant maintenance.
A41: Cluster peaks are sums without diversity. Spare capacity cannot automatically transfer between buildings.
A42: Payback excludes financing, future tariff changes, equipment replacements and residual values.
A43: Use QA to review input validity and reconciliations. Review engineering limits in Guide and sources.

Sheet Assumptions
A2: Editable programme assumptions
A4: Prices include CCL and exclude VAT. Planning costs and engineering assumptions are illustrative. Research date: 25 October 2026.
A6: Driver | B6: Value | C6: Unit | D6: Basis | E6: Source ID | F6: Use / limitation
A7: Electricity benchmark | B7: 24.51 | C7: p/kWh | D7: DESNZ Q2 2026 all bands | E7: S02 | F7: Rounded from 24.50920275. Fully delivered average, not a marginal tariff.
A8: Gas benchmark | B8: 5.28 | C8: p/kWh GCV | D8: DESNZ Q2 2026 all bands | E8: S02 | F8: Rounded from 5.27689274. Replace with university contract values.
A9: Gas combustion factor | B9: 0.18231 | C9: kgCO2e/kWh GCV | D9: DESNZ 2026 Fuels!D42 | E9: S01 | F9: Scope 1. Includes CO2, CH4 and N2O.
A10: Electricity factor | B10: 0.13096 | C10: kgCO2e/kWh | D10: DESNZ 2026 UK electricity!E25 | E10: S01 | F10: Scope 2 location-based. Excludes transmission losses and upstream fuels.
A11: PV annual yield | B11: 900 | C11: kWh/kWp/yr | D11: Planning assumption | E11: P01 | F11: Annual output before self-use. No shading or hourly matching model.
A12: SCOP multiplier | B12: 1 | C12: multiplier | D12: Planning assumption | E12: P01 | F12: Multiplies each building seasonal COP. Use to test annual performance.
A13: Unit heat-pump capacity | B13: 100 | C13: kWt/unit | D13: Planning assumption | E13: P01 | F13: Delivered heat at design conditions. Rounded up, no standby redundancy.
A14: Design COP | B14: 2.5 | C14: kWt/kWe | D14: Planning assumption | E14: P01 | F14: Used for peak electrical demand. Separate from annual seasonal COP.
A15: Installed HP cost | B15: 1000 | C15: £/kWt installed | D15: Planning allowance | E15: P01 | F15: Plant, installation, emitters and integration allowance. Replace with quotations.
A16: PV installation cost | B16: 1100 | C16: £/kWp | D16: Planning allowance | E16: P01 | F16: No battery. No grant or export income.
A17: Fabric works cost | B17: 160 | C17: £/treated m² | D17: Planning allowance | E17: P01 | F17: Applied to treated area, not automatically to total building floor area.
A18: Electrical upgrade cost | B18: 450 | C18: £/kWe shortfall | D18: Planning allowance | E18: P01 | F18: Linear screening allowance. Does not model transformer step costs.
... A23: PV maintenance | B23: 12 | C23: £/kWp/yr | D23: Planning allowance | E23: P01 | F23: Fabric maintenance excluded.
A24: Portfolio price ratio | B24: =B7/B8 -> 4.6420455 | C24: electricity / gas | D24: Calculated | E24: S02 | F24: Heat-pump bill savings depend strongly on this ratio.
A27: Colour key
A28: Amber / blue text = editable input
A29: White or pale blue = formula result
A31: S01–S02: official sources. P01: explicit planning assumptions. See Guide and sources for links and exclusions.

Sheet Energy
A2: Annual energy, OPEX and emissions
A4: Full gas-to-heat-pump conversion. Positive savings mean a reduction. All values are annual. Post-project gas is zero.
A6: Building ID | B6: Building | C6: Cluster | D6: Gas input kWh | E6: Other electricity kWh | F6: Boiler efficiency | G6: Useful heat kWh | H6: Heat reduction | I6: Post heat kWh | J6: Active SCOP | K6: HP electricity kWh | L6: PV kWp | M6: PV generation kWh | N6: PV self-used kWh | O6: PV exported kWh | P6: Grid import kWh | Q6: Baseline Scope 1 tCO2e | R6: Baseline Scope 2 tCO2e | S6: Baseline total tCO2e | T6: Post Scope 2 tCO2e | U6: Emissions saved tCO2e | V6: Emissions reduction | W6: Baseline energy £/yr | X6: Post energy £/yr | Y6: Bill saving £/yr | Z6: Baseline maintenance £/yr | AA6: Post maintenance £/yr | AB6: Baseline OPEX £/yr | AC6: Post OPEX £/yr | AD6: OPEX saving £/yr
A7: B01 | B7: =INDEX(Buildings!$B$7:$B$26,MATCH($A7,Buildings!$A$7:$A$26,0)) -> Alder Library | C7: =INDEX(Buildings!$C$7:$C$26,MATCH($A7,Buildings!$A$7:$A$26,0)) -> North | D7: =IF(ISNUMBER(INDEX(Buildings!$F$7:$F$26,MATCH($A7,Buildings!$A$7:$A$26,0))),INDEX(Buildings!$F$7:$F$26,MATCH($A7,Buildings!$A$7:$A$26,0)),NA()) -> 620000 | E7: =IF(ISNUMBER(INDEX(Buildings!$G$7:$G$26,MATCH($A7,Buildings!$A$7:$A$26,0))),INDEX(Buildings!$G$7:$G$26,MATCH($A7,Buildings!$A$7:$A$26,0)),NA()) -> 490000 | F7: =IF(INDEX(Buildings!$H$7:$H$26,MATCH($A7,Buildings!$A$7:$A$26,0))>0,INDEX(Buildings!$H$7:$H$26,MATCH($A7,Buildings!$A$7:$A$26,0)),NA()) -> 0.82 | G7: =D7*F7 -> 508400 | H7: =INDEX(Buildings!$I$7:$I$26,MATCH($A7,Buildings!$A$7:$A$26,0)) -> 0.18 | I7: =G7*(1-H7) -> 416888 | J7: =INDEX(Buildings!$L$7:$L$26,MATCH($A7,Buildings!$A$7:$A$26,0))*Assumptions!$B$12 -> 3.3 | K7: =I7/J7 -> 126329.7 | L7: =INDEX(Buildings!$M$7:$M$26,MATCH($A7,Buildings!$A$7:$A$26,0)) -> 90 | M7: =L7*Assumptions!$B$11 -> 81000 | N7: =MIN(M7*INDEX(Buildings!$N$7:$N$26,MATCH($A7,Buildings!$A$7:$A$26,0)),E7+K7) -> 64800 | O7: =M7-N7 -> 16200 | P7: =E7+K7-N7 -> 551529.7 | Q7: =D7*Assumptions!$B$9/1000 -> 113.0322 | R7: =E7*Assumptions!$B$10/1000 -> 64.1704 | S7: =Q7+R7 -> 177.2026 | T7: =P7*Assumptions!$B$10/1000 -> 72.228329 | U7: =S7-T7 -> 104.97427 | V7: =IF(S7=0,0,U7/S7) -> 0.5923969 | W7: =(D7*Assumptions!$B$8+E7*Assumptions!$B$7)/100 -> 152835 | X7: =P7*Assumptions!$B$7/100 -> 135179.93 | Y7: =W7-X7 -> 17655.071 | Z7: =INDEX(Buildings!$J$7:$J$26,MATCH($A7,Buildings!$A$7:$A$26,0))*Assumptions!$B$21 -> 3150 | AA7: =INDEX(CAPEX!$G$7:$G$26,MATCH($A7,CAPEX!$A$7:$A$26,0))*Assumptions!$B$22+L7*Assumptions!$B$23 -> 6480 | AB7: =W7+Z7 -> 155985 | AC7: =X7+AA7 -> 141659.93 | AD7: =AB7-AC7 -> 14325.071
A8: B02 | B8: =INDEX(Buildings!$B$7:$B$26,MATCH($A8,Buildings!$A$7:$A$26,0)) -> Birch Teaching Centre | C8: =INDEX(Buildings!$C$7:$C$26,MATCH($A8,Buildings!$A$7:$A$26,0)) -> North | D8: =IF(ISNUMBER(INDEX(Buildings!$F$7:$F$26,MATCH($A8,Buildings!$A$7:$A$26,0))),INDEX(Buildings!$F$7:$F$26,MATCH($A8,Buildings!$A$7:$A$26,0)),NA()) -> 510000 | E8: =IF(ISNUMBER(INDEX(Buildings!$G$7:$G$26,MATCH($A8,Buildings!$A$7:$A$26,0))),INDEX(Buildings!$G$7:$G$26,MATCH($A8,Buildings!$A$7:$A$26,0)),NA()) -> 320000 | F8: =IF(INDEX(Buildings!$H$7:$H$26,MATCH($A8,Buildings!$A$7:$A$26,0))>0,INDEX(Buildings!$H$7:$H$26,MATCH($A8,Buildings!$A$7:$A$26,0)),NA()) -> 0.86 | G8: =D8*F8 -> 438600 | H8: =INDEX(Buildings!$I$7:$I$26,MATCH($A8,Buildings!$A$7:$A$26,0)) -> 0.22 | I8: =G8*(1-H8) -> 342108 | J8: =INDEX(Buildings!$L$7:$L$26,MATCH($A8,Buildings!$A$7:$A$26,0))*Assumptions!$B$12 -> 3.4 | K8: =I8/J8 -> 100620 | L8: =INDEX(Buildings!$M$7:$M$26,MATCH($A8,Buildings!$A$7:$A$26,0)) -> 75 | M8: =L8*Assumptions!$B$11 -> 67500 | N8: =MIN(M8*INDEX(Buildings!$N$7:$N$26,MATCH($A8,Buildings!$A$7:$A$26,0)),E8+K8) -> 50625 | O8: =M8-N8 -> 16875 | P8: =E8+K8-N8 -> 369995 | Q8: =D8*Assumptions!$B$9/1000 -> 92.9781 | R8: =E8*Assumptions!$B$10/1000 -> 41.9072 | S8: =Q8+R8 -> 134.8853 | T8: =P8*Assumptions!$B$10/1000 -> 48.454545 | U8: =S8-T8 -> 86.430755 | V8: =IF(S8=0,0,U8/S8) -> 0.64077223 | W8: =(D8*Assumptions!$B$8+E8*Assumptions!$B$7)/100 -> 105360 | X8: =P8*Assumptions!$B$7/100 -> 90685.775 | Y8: =W8-X8 -> 14674.225 | Z8: =INDEX(Buildings!$J$7:$J$26,MATCH($A8,Buildings!$A$7:$A$26,0))*Assumptions!$B$21 -> 2520 | AA8: =INDEX(CAPEX!$G$7:$G$26,MATCH($A8,CAPEX!$A$7:$A$26,0))*Assumptions!$B$22+L8*Assumptions!$B$23 -> 6300 | AB8: =W8+Z8 -> 107880 | AC8: =X8+AA8 -> 96985.775 | AD8: =AB8-AC8 -> 10894.225
A9: B03 | B9: =INDEX(Buildings!$B$7:$B$26,MATCH($A9,Buildings!$A$7:$A$26,0)) -> Cedar Chemistry Lab | C9: =INDEX(Buildings!$C$7:$C$26,MATCH($A9,Buildings!$A$7:$A$26,0)) -> North | D9: =IF(ISNUMBER(INDEX(Buildings!$F$7:$F$26,MATCH($A9,Buildings!$A$7:$A$26,0))),INDEX(Buildings!$F$7:$F$26,MATCH($A9,Buildings!$A$7:$A$26,0)),NA()) -> 1680000 | E9: =IF(ISNUMBER(INDEX(Buildings!$G$7:$G$26,MATCH($A9,Buildings!$A$7:$A$26,0))),INDEX(Buildings!$G$7:$G$26,MATCH($A9,Buildings!$A$7:$A$26,0)),NA()) -> 2840000 | F9: =IF(INDEX(Buildings!$H$7:$H$26,MATCH($A9,Buildings!$A$7:$A$26,0))>0,INDEX(Buildings!$H$7:$H$26,MATCH($A9,Buildings!$A$7:$A$26,0)),NA()) -> 0.8 | G9: =D9*F9 -> 1344000 | H9: =INDEX(Buildings!$I$7:$I$26,MATCH($A9,Buildings!$A$7:$A$26,0)) -> 0.12 | I9: =G9*(1-H9) -> 1182720 | J9: =INDEX(Buildings!$L$7:$L$26,MATCH($A9,Buildings!$A$7:$A$26,0))*Assumptions!$B$12 -> 2.9 | K9: =I9/J9 -> 407834.48 | L9: =INDEX(Buildings!$M$7:$M$26,MATCH($A9,Buildings!$A$7:$A$26,0)) -> 150 | M9: =L9*Assumptions!$B$11 -> 135000 | N9: =MIN(M9*INDEX(Buildings!$N$7:$N$26,MATCH($A9,Buildings!$A$7:$A$26,0)),E9+K9) -> 128250 | O9: =M9-N9 -> 6750 | P9: =E9+K9-N9 -> 3119584.5 | Q9: =D9*Assumptions!$B$9/1000 -> 306.2808 | R9: =E9*Assumptions!$B$10/1000 -> 371.9264 | S9: =Q9+R9 -> 678.2072 | T9: =P9*Assumptions!$B$10/1000 -> 408.54078 | U9: =S9-T9 -> 269.66642 | V9: =IF(S9=0,0,U9/S9) -> 0.39761656 | W9: =(D9*Assumptions!$B$8+E9*Assumptions!$B$7)/100 -> 784788 | X9: =P9*Assumptions!$B$7/100 -> 764610.16 | Y9: =W9-X9 -> 20177.843 | Z9: =INDEX(Buildings!$J$7:$J$26,MATCH($A9,Buildings!$A$7:$A$26,0))*Assumptions!$B$21 -> 7480 | AA9: =INDEX(CAPEX!$G$7:$G$26,MATCH($A9,CAPEX!$A$7:$A$26,0))*Assumptions!$B$22+L9*Assumptions!$B$23 -> 14400 | AB9: =W9+Z9 -> 792268 | AC9: =X9+AA9 -> 779010.16 | AD9: =AB9-AC9 -> 13257.843
A10: B04 | B10: =INDEX(Buildings!$B$7:$B$26,MATCH($A10,Buildings!$A$7:$A$26,0)) -> Dove Administration | C10: =INDEX(Buildings!$C$7:$C$26,MATCH($A10,Buildings!$A$7:$A$26,0)) -> North | D10: =IF(ISNUMBER(INDEX(Buildings!$F$7:$F$26,MATCH($A10,Buildings!$A$7:$A$26,0))),INDEX(Buildings!$F$7:$F$26,MATCH($A10,Buildings!$A$7:$A$26,0)),NA()) -> 310000 | E10: =IF(ISNUMBER(INDEX(Buildings!$G$7:$G$26,MATCH($A10,Buildings!$A$7:$A$26,0))),INDEX(Buildings!$G$7:$G$26,MATCH($A10,Buildings!$A$7:$A$26,0)),NA()) -> 210000 | F10: =IF(INDEX(Buildings!$H$7:$H$26,MATCH($A10,Buildings!$A$7:$A$26,0))>0,INDEX(Buildings!$H$7:$H$26,MATCH($A10,Buildings!$A$7:$A$26,0)),NA()) -> 0.88 | G10: =D10*F10 -> 272800 | H10: =INDEX(Buildings!$I$7:$I$26,MATCH($A10,Buildings!$A$7:$A$26,0)) -> 0.25 | I10: =G10*(1-H10) -> 204600 | J10: =INDEX(Buildings!$L$7:$L$26,MATCH($A10,Buildings!$A$7:$A$26,0))*Assumptions!$B$12 -> 3.5 | K10: =I10/J10 -> 58457.143 | L10: =INDEX(Buildings!$M$7:$M$26,MATCH($A10,Buildings!$A$7:$A$26,0)) -> 40 | M10: =L10*Assumptions!$B$11 -> 36000 | N10: =MIN(M10*INDEX(Buildings!$N$7:$N$26,MATCH($A10,Buildings!$A$7:$A$26,0)),E10+K10) -> 25200 | O10: =M10-N10 -> 10800 | P10: =E10+K10-N10 -> 243257.14 | Q10: =D10*Assumptions!$B$9/1000 -> 56.5161 | R10: =E10*Assumptions!$B$10/1000 -> 27.5016 | S10: =Q10+R10 -> 84.0177 | T10: =P10*Assumptions!$B$10/1000 -> 31.856955 | U10: =S10-T10 -> 52.160745 | V10: =IF(S10=0,0,U10/S10) -> 0.62083043 | W10: =(D10*Assumptions!$B$8+E10*Assumptions!$B$7)/100 -> 67839 | X10: =P10*Assumptions!$B$7/100 -> 59622.326 | Y10: =W10-X10 -> 8216.6743 | Z10: =INDEX(Buildings!$J$7:$J$26,MATCH($A10,Buildings!$A$7:$A$26,0))*Assumptions!$B$21 -> 1560 | AA10: =INDEX(CAPEX!$G$7:$G$26,MATCH($A10,CAPEX!$A$7:$A$26,0))*Assumptions!$B$22+L10*Assumptions!$B$23 -> 4080 | AB10: =W10+Z10 -> 69399 | AC10: =X10+AA10 -> 63702.326 | AD10: =AB10-AC10 -> 5696.6743
A11: B05 | B11: =INDEX(Buildings!$B$7:$B$26,MATCH($A11,Buildings!$A$7:$A$26,0)) -> Elm Residence | C11: =INDEX(Buildings!$C$7:$C$26,MATCH($A11,Buildings!$A$7:$A$26,0)) -> North | D11: =IF(ISNUMBER(INDEX(Buildings!$F$7:$F$26,MATCH($A11,Buildings!$A$7:$A$26,0))),INDEX(Buildings!$F$7:$F$26,MATCH($A11,Buildings!$A$7:$A$26,0)),NA()) -> 1020000 | E11: =IF(ISNUMBER(INDEX(Buildings!$G$7:$G$26,MATCH($A11,Buildings!$A$7:$A$26,0))),INDEX(Buildings!$G$7:$G$26,MATCH($A11,Buildings!$A$7:$A$26,0)),NA()) -> 460000 | F11: =IF(INDEX(Buildings!$H$7:$H$26,MATCH($A11,Buildings!$A$7:$A$26,0))>0,INDEX(Buildings!$H$7:$H$26,MATCH($A11,Buildings!$A$7:$A$26,0)),NA()) -> 0.84 | G11: =D11*F11 -> 856800 | H11: =INDEX(Buildings!$I$7:$I$26,MATCH($A11,Buildings!$A$7:$A$26,0)) -> 0.16 | I11: =G11*(1-H11) -> 719712 | J11: =INDEX(Buildings!$L$7:$L$26,MATCH($A11,Buildings!$A$7:$A$26,0))*Assumptions!$B$12 -> 3.1 | K11: =I11/J11 -> 232165.16 | L11: =INDEX(Buildings!$M$7:$M$26,MATCH($A11,Buildings!$A$7:$A$26,0)) -> 110 | M11: =L11*Assumptions!$B$11 -> 99000 | N11: =MIN(M11*INDEX(Buildings!$N$7:$N$26,MATCH($A11,Buildings!$A$7:$A$26,0)),E11+K11) -> 84150 | O11: =M11-N11 -> 14850 | P11: =E11+K11-N11 -> 608015.16 | Q11: =D11*Assumptions!$B$9/1000 -> 185.9562 | R11: =E11*Assumptions!$B$10/1000 -> 60.2416 | S11: =Q11+R11 -> 246.1978 | T11: =P11*Assumptions!$B$10/1000 -> 79.625666 | U11: =S11-T11 -> 166.57213 | V11: =IF(S11=0,0,U11/S11) -> 0.67657848 | W11: =(D11*Assumptions!$B$8+E11*Assumptions!$B$7)/100 -> 166602 | X11: =P11*Assumptions!$B$7/100 -> 149024.52 | Y11: =W11-X11 -> 17577.484 | Z11: =INDEX(Buildings!$J$7:$J$26,MATCH($A11,Buildings!$A$7:$A$26,0))*Assumptions!$B$21 -> 4320 | AA11: =INDEX(CAPEX!$G$7:$G$26,MATCH($A11,CAPEX!$A$7:$A$26,0))*Assumptions!$B$22+L11*Assumptions!$B$23 -> 8520 | AB11: =W11+Z11 -> 170922 | AC11: =X11+AA11 -> 157544.52 | AD11: =AB11-AC11 -> 13377.484
A12: B06 | B12: =INDEX(Buildings!$B$7:$B$26,MATCH($A12,Buildings!$A$7:$A$26,0)) -> Fern Engineering | C12: =INDEX(Buildings!$C$7:$C$26,MATCH($A12,Buildings!$A$7:$A$26,0)) -> Central | D12: =IF(ISNUMBER(INDEX(Buildings!$F$7:$F$26,MATCH($A12,Buildings!$A$7:$A$26,0))),INDEX(Buildings!$F$7:$F$26,MATCH($A12,Buildings!$A$7:$A$26,0)),NA()) -> 1390000 | E12: =IF(ISNUMBER(INDEX(Buildings!$G$7:$G$26,MATCH($A12,Buildings!$A$7:$A$26,0))),INDEX(Buildings!$G$7:$G$26,MATCH($A12,Buildings!$A$7:$A$26,0)),NA()) -> 1530000 | F12: =IF(INDEX(Buildings!$H$7:$H$26,MATCH($A12,Buildings!$A$7:$A$26,0))>0,INDEX(Buildings!$H$7:$H$26,MATCH($A12,Buildings!$A$7:$A$26,0)),NA()) -> 0.82 | G12: =D12*F12 -> 1139800 | H12: =INDEX(Buildings!$I$7:$I$26,MATCH($A12,Buildings!$A$7:$A$26,0)) -> 0.18 | I12: =G12*(1-H12) -> 934636 | J12: =INDEX(Buildings!$L$7:$L$26,MATCH($A12,Buildings!$A$7:$A$26,0))*Assumptions!$B$12 -> 3.3 | K12: =I12/J12 -> 283223.03 | L12: =INDEX(Buildings!$M$7:$M$26,MATCH($A12,Buildings!$A$7:$A$26,0)) -> 180 | M12: =L12*Assumptions!$B$11 -> 162000 | N12: =MIN(M12*INDEX(Buildings!$N$7:$N$26,MATCH($A12,Buildings!$A$7:$A$26,0)),E12+K12) -> 129600 | O12: =M12-N12 -> 32400 | P12: =E12+K12-N12 -> 1683623 | Q12: =D12*Assumptions!$B$9/1000 -> 253.4109 | R12: =E12*Assumptions!$B$10/1000 -> 200.3688 | S12: =Q12+R12 -> 453.7797 | T12: =P12*Assumptions!$B$10/1000 -> 220.48727 | U12: =S12-T12 -> 233.29243 | V12: =IF(S12=0,0,U12/S12) -> 0.51410944 | W12: =(D12*Assumptions!$B$8+E12*Assumptions!$B$7)/100 -> 448395 | X12: =P12*Assumptions!$B$7/100 -> 412656 | Y12: =W12-X12 -> 35738.995 | Z12: =INDEX(Buildings!$J$7:$J$26,MATCH($A12,Buildings!$A$7:$A$26,0))*Assumptions!$B$21 -> 5700 | AA12: =INDEX(CAPEX!$G$7:$G$26,MATCH($A12,CAPEX!$A$7:$A$26,0))*Assumptions!$B$22+L12*Assumptions!$B$23 -> 11160 | AB12: =W12+Z12 -> 454095 | AC12: =X12+AA12 -> 423816 | AD12: =AB12-AC12 -> 30278.995
A13: B07 | B13: =INDEX(Buildings!$B$7:$B$26,MATCH($A13,Buildings!$A$7:$A$26,0)) -> Grove Humanities | C13: =INDEX(Buildings!$C$7:$C$26,MATCH($A13,Buildings!$A$7:$A$26,0)) -> Central | D13: =IF(ISNUMBER(INDEX(Buildings!$F$7:$F$26,MATCH($A13,Buildings!$A$7:$A$26,0))),INDEX(Buildings!$F$7:$F$26,MATCH($A13,Buildings!$A$7:$A$26,0)),NA()) -> 470000 | E13: =IF(ISNUMBER(INDEX(Buildings!$G$7:$G$26,MATCH($A13,Buildings!$A$7:$A$26,0))),INDEX(Buildings!$G$7:$G$26,MATCH($A13,Buildings!$A$7:$A$26,0)),NA()) -> 260000 | F13: =IF(INDEX(Buildings!$H$7:$H$26,MATCH($A13,Buildings!$A$7:$A$26,0))>0,INDEX(Buildings!$H$7:$H$26,MATCH($A13,Buildings!$A$7:$A$26,0)),NA()) -> 0.86 | G13: =D13*F13 -> 404200 | H13: =INDEX(Buildings!$I$7:$I$26,MATCH($A13,Buildings!$A$7:$A$26,0)) -> 0.22 | I13: =G13*(1-H13) -> 315276 | J13: =INDEX(Buildings!$L$7:$L$26,MATCH($A13,Buildings!$A$7:$A$26,0))*Assumptions!$B$12 -> 3.4 | K13: =I13/J13 -> 92728.235 | L13: =INDEX(Buildings!$M$7:$M$26,MATCH($A13,Buildings!$A$7:$A$26,0)) -> 60 | M13: =L13*Assumptions!$B$11 -> 54000 | N13: =MIN(M13*INDEX(Buildings!$N$7:$N$26,MATCH($A13,Buildings!$A$7:$A$26,0)),E13+K13) -> 40500 | O13: =M13-N13 -> 13500 | P13: =E13+K13-N13 -> 312228.24 | Q13: =D13*Assumptions!$B$9/1000 -> 85.6857 | R13: =E13*Assumptions!$B$10/1000 -> 34.0496 | S13: =Q13+R13 -> 119.7353 | T13: =P13*Assumptions!$B$10/1000 -> 40.88941 | U13: =S13-T13 -> 78.84589 | V13: =IF(S13=0,0,U13/S13) -> 0.65850163 | W13: =(D13*Assumptions!$B$8+E13*Assumptions!$B$7)/100 -> 88542 | X13: =P13*Assumptions!$B$7/100 -> 76527.14 | Y13: =W13-X13 -> 12014.86 | Z13: =INDEX(Buildings!$J$7:$J$26,MATCH($A13,Buildings!$A$7:$A$26,0))*Assumptions!$B$21 -> 2240 | AA13: =INDEX(CAPEX!$G$7:$G$26,MATCH($A13,CAPEX!$A$7:$A$26,0))*Assumptions!$B$22+L13*Assumptions!$B$23 -> 4320 | AB13: =W13+Z13 -> 90782 | AC13: =X13+AA13 -> 80847.14 | AD13: =AB13-AC13 -> 9934.8595
A14: B08 | B14: =INDEX(Buildings!$B$7:$B$26,MATCH($A14,Buildings!$A$7:$A$26,0)) -> Hazel Sports Centre | C14: =INDEX(Buildings!$C$7:$C$26,MATCH($A14,Buildings!$A$7:$A$26,0)) -> Central | D14: =IF(ISNUMBER(INDEX(Buildings!$F$7:$F$26,MATCH($A14,Buildings!$A$7:$A$26,0))),INDEX(Buildings!$F$7:$F$26,MATCH($A14,Buildings!$A$7:$A$26,0)),NA()) -> 1750000 | E14: =IF(ISNUMBER(INDEX(Buildings!$G$7:$G$26,MATCH($A14,Buildings!$A$7:$A$26,0))),INDEX(Buildings!$G$7:$G$26,MATCH($A14,Buildings!$A$7:$A$26,0)),NA()) -> 860000 | F14: =IF(INDEX(Buildings!$H$7:$H$26,MATCH($A14,Buildings!$A$7:$A$26,0))>0,INDEX(Buildings!$H$7:$H$26,MATCH($A14,Buildings!$A$7:$A$26,0)),NA()) -> 0.8 | G14: =D14*F14 -> 1400000 | H14: =INDEX(Buildings!$I$7:$I$26,MATCH($A14,Buildings!$A$7:$A$26,0)) -> 0.12 | I14: =G14*(1-H14) -> 1232000 | J14: =INDEX(Buildings!$L$7:$L$26,MATCH($A14,Buildings!$A$7:$A$26,0))*Assumptions!$B$12 -> 2.9 | K14: =I14/J14 -> 424827.59 | L14: =INDEX(Buildings!$M$7:$M$26,MATCH($A14,Buildings!$A$7:$A$26,0)) -> 140 | M14: =L14*Assumptions!$B$11 -> 126000 | N14: =MIN(M14*INDEX(Buildings!$N$7:$N$26,MATCH($A14,Buildings!$A$7:$A$26,0)),E14+K14) -> 119700 | O14: =M14-N14 -> 6300 | P14: =E14+K14-N14 -> 1165127.6 | Q14: =D14*Assumptions!$B$9/1000 -> 319.0425 | R14: =E14*Assumptions!$B$10/1000 -> 112.6256 | S14: =Q14+R14 -> 431.6681 | T14: =P14*Assumptions!$B$10/1000 -> 152.58511 | U14: =S14-T14 -> 279.08299 | V14: =IF(S14=0,0,U14/S14) -> 0.64652216 | W14: =(D14*Assumptions!$B$8+E14*Assumptions!$B$7)/100 -> 303186 | X14: =P14*Assumptions!$B$7/100 -> 285572.77 | Y14: =W14-X14 -> 17613.229 | Z14: =INDEX(Buildings!$J$7:$J$26,MATCH($A14,Buildings!$A$7:$A$26,0))*Assumptions!$B$21 -> 7150 | AA14: =INDEX(CAPEX!$G$7:$G$26,MATCH($A14,CAPEX!$A$7:$A$26,0))*Assumptions!$B$22+L14*Assumptions!$B$23 -> 14280 | AB14: =W14+Z14 -> 310336 | AC14: =X14+AA14 -> 299852.77 | AD14: =AB14-AC14 -> 10483.229
A15: B09 | B15: =INDEX(Buildings!$B$7:$B$26,MATCH($A15,Buildings!$A$7:$A$26,0)) -> Iris Computing | C15: =INDEX(Buildings!$C$7:$C$26,MATCH($A15,Buildings!$A$7:$A$26,0)) -> Central | D15: =IF(ISNUMBER(INDEX(Buildings!$F$7:$F$26,MATCH($A15,Buildings!$A$7:$A$26,0))),INDEX(Buildings!$F$7:$F$26,MATCH($A15,Buildings!$A$7:$A$26,0)),NA()) -> 450000 | E15: =IF(ISNUMBER(INDEX(Buildings!$G$7:$G$26,MATCH($A15,Buildings!$A$7:$A$26,0))),INDEX(Buildings!$G$7:$G$26,MATCH($A15,Buildings!$A$7:$A$26,0)),NA()) -> 2380000 | F15: =IF(INDEX(Buildings!$H$7:$H$26,MATCH($A15,Buildings!$A$7:$A$26,0))>0,INDEX(Buildings!$H$7:$H$26,MATCH($A15,Buildings!$A$7:$A$26,0)),NA()) -> 0.88 | G15: =D15*F15 -> 396000 | H15: =INDEX(Buildings!$I$7:$I$26,MATCH($A15,Buildings!$A$7:$A$26,0)) -> 0.25 | I15: =G15*(1-H15) -> 297000 | J15: =INDEX(Buildings!$L$7:$L$26,MATCH($A15,Buildings!$A$7:$A$26,0))*Assumptions!$B$12 -> 3.5 | K15: =I15/J15 -> 84857.143 | L15: =INDEX(Buildings!$M$7:$M$26,MATCH($A15,Buildings!$A$7:$A$26,0)) -> 120 | M15: =L15*Assumptions!$B$11 -> 108000 | N15: =MIN(M15*INDEX(Buildings!$N$7:$N$26,MATCH($A15,Buildings!$A$7:$A$26,0)),E15+K15) -> 75600 | O15: =M15-N15 -> 32400 | P15: =E15+K15-N15 -> 2389257.1 | Q15: =D15*Assumptions!$B$9/1000 -> 82.0395 | R15: =E15*Assumptions!$B$10/1000 -> 311.6848 | S15: =Q15+R15 -> 393.7243 | T15: =P15*Assumptions!$B$10/1000 -> 312.89712 | U15: =S15-T15 -> 80.827185 | V15: =IF(S15=0,0,U15/S15) -> 0.20528879 | W15: =(D15*Assumptions!$B$8+E15*Assumptions!$B$7)/100 -> 607098 | X15: =P15*Assumptions!$B$7/100 -> 585606.93 | Y15: =W15-X15 -> 21491.074 | Z15: =INDEX(Buildings!$J$7:$J$26,MATCH($A15,Buildings!$A$7:$A$26,0))*Assumptions!$B$21 -> 3120 | AA15: =INDEX(CAPEX!$G$7:$G$26,MATCH($A15,CAPEX!$A$7:$A$26,0))*Assumptions!$B$22+L15*Assumptions!$B$23 -> 6840 | AB15: =W15+Z15 -> 610218 | AC15: =X15+AA15 -> 592446.93 | AD15: =AB15-AC15 -> 17771.074
A16: B10 | B16: =INDEX(Buildings!$B$7:$B$26,MATCH($A16,Buildings!$A$7:$A$26,0)) -> Juniper Research | C16: =INDEX(Buildings!$C$7:$C$26,MATCH($A16,Buildings!$A$7:$A$26,0)) -> Central | D16: =IF(ISNUMBER(INDEX(Buildings!$F$7:$F$26,MATCH($A16,Buildings!$A$7:$A$26,0))),INDEX(Buildings!$F$7:$F$26,MATCH($A16,Buildings!$A$7:$A$26,0)),NA()) -> 1460000 | E16: =IF(ISNUMBER(INDEX(Buildings!$G$7:$G$26,MATCH($A16,Buildings!$A$7:$A$26,0))),INDEX(Buildings!$G$7:$G$26,MATCH($A16,Buildings!$A$7:$A$26,0)),NA()) -> 2490000 | F16: =IF(INDEX(Buildings!$H$7:$H$26,MATCH($A16,Buildings!$A$7:$A$26,0))>0,INDEX(Buildings!$H$7:$H$26,MATCH($A16,Buildings!$A$7:$A$26,0)),NA()) -> 0.84 | G16: =D16*F16 -> 1226400 | H16: =INDEX(Buildings!$I$7:$I$26,MATCH($A16,Buildings!$A$7:$A$26,0)) -> 0.16 | I16: =G16*(1-H16) -> 1030176 | J16: =INDEX(Buildings!$L$7:$L$26,MATCH($A16,Buildings!$A$7:$A$26,0))*Assumptions!$B$12 -> 3.1 | K16: =I16/J16 -> 332314.84 | L16: =INDEX(Buildings!$M$7:$M$26,MATCH($A16,Buildings!$A$7:$A$26,0)) -> 170 | M16: =L16*Assumptions!$B$11 -> 153000 | N16: =MIN(M16*INDEX(Buildings!$N$7:$N$26,MATCH($A16,Buildings!$A$7:$A$26,0)),E16+K16) -> 130050 | O16: =M16-N16 -> 22950 | P16: =E16+K16-N16 -> 2692264.8 | Q16: =D16*Assumptions!$B$9/1000 -> 266.1726 | R16: =E16*Assumptions!$B$10/1000 -> 326.0904 | S16: =Q16+R16 -> 592.263 | T16: =P16*Assumptions!$B$10/1000 -> 352.579 | U16: =S16-T16 -> 239.684 | V16: =IF(S16=0,0,U16/S16) -> 0.40469183 | W16: =(D16*Assumptions!$B$8+E16*Assumptions!$B$7)/100 -> 687387 | X16: =P16*Assumptions!$B$7/100 -> 659874.11 | Y16: =W16-X16 -> 27512.888 | Z16: =INDEX(Buildings!$J$7:$J$26,MATCH($A16,Buildings!$A$7:$A$26,0))*Assumptions!$B$21 -> 5760 | AA16: =INDEX(CAPEX!$G$7:$G$26,MATCH($A16,CAPEX!$A$7:$A$26,0))*Assumptions!$B$22+L16*Assumptions!$B$23 -> 11040 | AB16: =W16+Z16 -> 693147 | AC16: =X16+AA16 -> 670914.11 | AD16: =AB16-AC16 -> 22232.888
A17: B11 | B17: =INDEX(Buildings!$B$7:$B$26,MATCH($A17,Buildings!$A$7:$A$26,0)) -> Kingfisher Hall | C17: =INDEX(Buildings!$C$7:$C$26,MATCH($A17,Buildings!$A$7:$A$26,0)) -> South | D17: =IF(ISNUMBER(INDEX(Buildings!$F$7:$F$26,MATCH($A17,Buildings!$A$7:$A$26,0))),INDEX(Buildings!$F$7:$F$26,MATCH($A17,Buildings!$A$7:$A$26,0)),NA()) -> 780000 | E17: =IF(ISNUMBER(INDEX(Buildings!$G$7:$G$26,MATCH($A17,Buildings!$A$7:$A$26,0))),INDEX(Buildings!$G$7:$G$26,MATCH($A17,Buildings!$A$7:$A$26,0)),NA()) -> 350000 | F17: =IF(INDEX(Buildings!$H$7:$H$26,MATCH($A17,Buildings!$A$7:$A$26,0))>0,INDEX(Buildings!$H$7:$H$26,MATCH($A17,Buildings!$A$7:$A$26,0)),NA()) -> 0.82 | G17: =D17*F17 -> 639600 | H17: =INDEX(Buildings!$I$7:$I$26,MATCH($A17,Buildings!$A$7:$A$26,0)) -> 0.18 | I17: =G17*(1-H17) -> 524472 | J17: =INDEX(Buildings!$L$7:$L$26,MATCH($A17,Buildings!$A$7:$A$26,0))*Assumptions!$B$12 -> 3.3 | K17: =I17/J17 -> 158930.91 | L17: =INDEX(Buildings!$M$7:$M$26,MATCH($A17,Buildings!$A$7:$A$26,0)) -> 85 | M17: =L17*Assumptions!$B$11 -> 76500 | N17: =MIN(M17*INDEX(Buildings!$N$7:$N$26,MATCH($A17,Buildings!$A$7:$A$26,0)),E17+K17) -> 61200 | O17: =M17-N17 -> 15300 | P17: =E17+K17-N17 -> 447730.91 | Q17: =D17*Assumptions!$B$9/1000 -> 142.2018 | R17: =E17*Assumptions!$B$10/1000 -> 45.836 | S17: =Q17+R17 -> 188.0378 | T17: =P17*Assumptions!$B$10/1000 -> 58.63484 | U17: =S17-T17 -> 129.40296 | V17: =IF(S17=0,0,U17/S17) -> 0.68817525 | W17: =(D17*Assumptions!$B$8+E17*Assumptions!$B$7)/100 -> 126969 | X17: =P17*Assumptions!$B$7/100 -> 109738.85 | Y17: =W17-X17 -> 17230.154 | Z17: =INDEX(Buildings!$J$7:$J$26,MATCH($A17,Buildings!$A$7:$A$26,0))*Assumptions!$B$21 -> 2930 | AA17: =INDEX(CAPEX!$G$7:$G$26,MATCH($A17,CAPEX!$A$7:$A$26,0))*Assumptions!$B$22+L17*Assumptions!$B$23 -> 6420 | AB17: =W17+Z17 -> 129899 | AC17: =X17+AA17 -> 116158.85 | AD17: =AB17-AC17 -> 13740.154
A18: B12 | B18: =INDEX(Buildings!$B$7:$B$26,MATCH($A18,Buildings!$A$7:$A$26,0)) -> Larch Medical Sciences | C18: =INDEX(Buildings!$C$7:$C$26,MATCH($A18,Buildings!$A$7:$A$26,0)) -> South | D18: =IF(ISNUMBER(INDEX(Buildings!$F$7:$F$26,MATCH($A18,Buildings!$A$7:$A$26,0))),INDEX(Buildings!$F$7:$F$26,MATCH($A18,Buildings!$A$7:$A$26,0)),NA()) -> 2050000 | E18: =IF(ISNUMBER(INDEX(Buildings!$G$7:$G$26,MATCH($A18,Buildings!$A$7:$A$26,0))),INDEX(Buildings!$G$7:$G$26,MATCH($A18,Buildings!$A$7:$A$26,0)),NA()) -> 3620000 | F18: =IF(INDEX(Buildings!$H$7:$H$26,MATCH($A18,Buildings!$A$7:$A$26,0))>0,INDEX(Buildings!$H$7:$H$26,MATCH($A18,Buildings!$A$7:$A$26,0)),NA()) -> 0.86 | G18: =D18*F18 -> 1763000 | H18: =INDEX(Buildings!$I$7:$I$26,MATCH($A18,Buildings!$A$7:$A$26,0)) -> 0.22 | I18: =G18*(1-H18) -> 1375140 | J18: =INDEX(Buildings!$L$7:$L$26,MATCH($A18,Buildings!$A$7:$A$26,0))*Assumptions!$B$12 -> 3.4 | K18: =I18/J18 -> 404452.94 | L18: =INDEX(Buildings!$M$7:$M$26,MATCH($A18,Buildings!$A$7:$A$26,0)) -> 200 | M18: =L18*Assumptions!$B$11 -> 180000 | N18: =MIN(M18*INDEX(Buildings!$N$7:$N$26,MATCH($A18,Buildings!$A$7:$A$26,0)),E18+K18) -> 135000 | O18: =M18-N18 -> 45000 | P18: =E18+K18-N18 -> 3889452.9 | Q18: =D18*Assumptions!$B$9/1000 -> 373.7355 | R18: =E18*Assumptions!$B$10/1000 -> 474.0752 | S18: =Q18+R18 -> 847.8107 | T18: =P18*Assumptions!$B$10/1000 -> 509.36276 | U18: =S18-T18 -> 338.44794 | V18: =IF(S18=0,0,U18/S18) -> 0.39920225 | W18: =(D18*Assumptions!$B$8+E18*Assumptions!$B$7)/100 -> 995502 | X18: =P18*Assumptions!$B$7/100 -> 953304.92 | Y18: =W18-X18 -> 42197.084 | Z18: =INDEX(Buildings!$J$7:$J$26,MATCH($A18,Buildings!$A$7:$A$26,0))*Assumptions!$B$21 -> 5950 | AA18: =INDEX(CAPEX!$G$7:$G$26,MATCH($A18,CAPEX!$A$7:$A$26,0))*Assumptions!$B$22+L18*Assumptions!$B$23 -> 11400 | AB18: =W18+Z18 -> 1001452 | AC18: =X18+AA18 -> 964704.92 | AD18: =AB18-AC18 -> 36747.084
... A26: B20 | B26: =INDEX(Buildings!$B$7:$B$26,MATCH($A26,Buildings!$A$7:$A$26,0)) -> Willow Innovation | C26: =INDEX(Buildings!$C$7:$C$26,MATCH($A26,Buildings!$A$7:$A$26,0)) -> West | D26: =IF(ISNUMBER(INDEX(Buildings!$F$7:$F$26,MATCH($A26,Buildings!$A$7:$A$26,0))),INDEX(Buildings!$F$7:$F$26,MATCH($A26,Buildings!$A$7:$A$26,0)),NA()) -> 920000 | E26: =IF(ISNUMBER(INDEX(Buildings!$G$7:$G$26,MATCH($A26,Buildings!$A$7:$A$26,0))),INDEX(Buildings!$G$7:$G$26,MATCH($A26,Buildings!$A$7:$A$26,0)),NA()) -> 1660000 | F26: =IF(INDEX(Buildings!$H$7:$H$26,MATCH($A26,Buildings!$A$7:$A$26,0))>0,INDEX(Buildings!$H$7:$H$26,MATCH($A26,Buildings!$A$7:$A$26,0)),NA()) -> 0.84 | G26: =D26*F26 -> 772800 | H26: =INDEX(Buildings!$I$7:$I$26,MATCH($A26,Buildings!$A$7:$A$26,0)) -> 0.16 | I26: =G26*(1-H26) -> 649152 | J26: =INDEX(Buildings!$L$7:$L$26,MATCH($A26,Buildings!$A$7:$A$26,0))*Assumptions!$B$12 -> 3.1 | K26: =I26/J26 -> 209403.87 | L26: =INDEX(Buildings!$M$7:$M$26,MATCH($A26,Buildings!$A$7:$A$26,0)) -> 155 | M26: =L26*Assumptions!$B$11 -> 139500 | N26: =MIN(M26*INDEX(Buildings!$N$7:$N$26,MATCH($A26,Buildings!$A$7:$A$26,0)),E26+K26) -> 118575 | O26: =M26-N26 -> 20925 | P26: =E26+K26-N26 -> 1750828.9 | Q26: =D26*Assumptions!$B$9/1000 -> 167.7252 | R26: =E26*Assumptions!$B$10/1000 -> 217.3936 | S26: =Q26+R26 -> 385.1188 | T26: =P26*Assumptions!$B$10/1000 -> 229.28855 | U26: =S26-T26 -> 155.83025 | V26: =IF(S26=0,0,U26/S26) -> 0.40462904 | W26: =(D26*Assumptions!$B$8+E26*Assumptions!$B$7)/100 -> 455442 | X26: =P26*Assumptions!$B$7/100 -> 429128.16 | Y26: =W26-X26 -> 26313.844 | Z26: =INDEX(Buildings!$J$7:$J$26,MATCH($A26,Buildings!$A$7:$A$26,0))*Assumptions!$B$21 -> 5120 | AA26: =INDEX(CAPEX!$G$7:$G$26,MATCH($A26,CAPEX!$A$7:$A$26,0))*Assumptions!$B$22+L26*Assumptions!$B$23 -> 10860 | AB26: =W26+Z26 -> 460562 | AC26: =X26+AA26 -> 439988.16 | AD26: =AB26-AC26 -> 20573.844
B28: Portfolio total | D28: =SUM(D7:D26) -> 19000000 | E28: =SUM(E7:E26) -> 23200000 | G28: =SUM(G7:G26) -> 15921600 | I28: =SUM(I7:I26) -> 13009760 | K28: =SUM(K7:K26) -> 4069651.9 | L28: =SUM(L7:L26) -> 2260 | M28: =SUM(M7:M26) -> 2034000 | N28: =SUM(N7:N26) -> 1647225 | O28: =SUM(O7:O26) -> 386775 | P28: =SUM(P7:P26) -> 25622427 | Q28: =SUM(Q7:Q26) -> 3463.89 | R28: =SUM(R7:R26) -> 3038.272 | ... U28: =SUM(U7:U26) -> 3146.649 | V28: =U28/S28 -> 0.48393888 | W28: =SUM(W7:W26) -> 6689520 | X28: =SUM(X7:X26) -> 6280056.8 | Y28: =SUM(Y7:Y26) -> 409463.16 | Z28: =SUM(Z7:Z26) -> 81660 | AA28: =SUM(AA7:AA26) -> 167520 | AB28: =SUM(AB7:AB26) -> 6771180 | AC28: =SUM(AC7:AC26) -> 6447576.8 | AD28: =SUM(AD7:AD26) -> 323603.16

Sheet CAPEX
A2: Equipment, electrical capacity and capital cost
A4: Peak electrical demand uses design COP and rounded installed capacity. PV provides no winter peak credit. Costs exclude VAT.
A6: Building ID | B6: Building | C6: Cluster | D6: Post design heat kWt | E6: Unit capacity kWt | F6: HP unit count | G6: Installed heat kWt | H6: Design COP | I6: Additional peak kWe | J6: Spare capacity kWe | K6: Shortfall kWe | L6: HP installation £ | M6: Electrical upgrade £ | N6: PV installation £ | O6: Fabric works £ | P6: Direct subtotal £ | Q6: Fees £ | R6: Contingency £ | S6: Total CAPEX £ | T6: OPEX saving £/yr | U6: Simple payback years | V6: CAPEX / annual tCO2e saved
A7: B01 | B7: =INDEX(Buildings!$B$7:$B$26,MATCH($A7,Buildings!$A$7:$A$26,0)) -> Alder Library | C7: =INDEX(Buildings!$C$7:$C$26,MATCH($A7,Buildings!$A$7:$A$26,0)) -> North | D7: =INDEX(Buildings!$J$7:$J$26,MATCH($A7,Buildings!$A$7:$A$26,0))*(1-INDEX(Buildings!$K$7:$K$26,MATCH($A7,Buildings!$A$7:$A$26,0))) -> 267.75 | E7: =Assumptions!$B$13 -> 100 | F7: =ROUNDUP(D7/E7,0) -> 3 | G7: =F7*E7 -> 300 | H7: =Assumptions!$B$14 -> 2.5 | I7: =G7/H7 -> 120 | J7: =INDEX(Buildings!$P$7:$P$26,MATCH($A7,Buildings!$A$7:$A$26,0)) -> 55 | K7: =MAX(0,I7-J7) -> 65 | L7: =G7*Assumptions!$B$15 -> 300000 | M7: =K7*Assumptions!$B$18 -> 29250 | N7: =INDEX(Buildings!$M$7:$M$26,MATCH($A7,Buildings!$A$7:$A$26,0))*Assumptions!$B$16 -> 99000 | O7: =INDEX(Buildings!$O$7:$O$26,MATCH($A7,Buildings!$A$7:$A$26,0))*Assumptions!$B$17 -> 201600 | P7: =SUM(L7:O7) -> 629850 | Q7: =P7*Assumptions!$B$19 -> 75582 | R7: =(P7+Q7)*Assumptions!$B$20 -> 141086.4 | S7: =SUM(P7:R7) -> 846518.4 | T7: =INDEX(Energy!$AD$7:$AD$26,MATCH($A7,Energy!$A$7:$A$26,0)) -> 14325.071 | U7: =IF(T7>0,S7/T7,"No saving") -> 59.093486 | V7: =IF(INDEX(Energy!$U$7:$U$26,MATCH($A7,Energy!$A$7:$A$26,0))>0,S7/INDEX(Energy!$U$7:$U$26,MATCH($A7,Energy!$A$7:$A$26,0)),"n.a.") -> 8064.056
A8: B02 | B8: =INDEX(Buildings!$B$7:$B$26,MATCH($A8,Buildings!$A$7:$A$26,0)) -> Birch Teaching Centre | C8: =INDEX(Buildings!$C$7:$C$26,MATCH($A8,Buildings!$A$7:$A$26,0)) -> North | D8: =INDEX(Buildings!$J$7:$J$26,MATCH($A8,Buildings!$A$7:$A$26,0))*(1-INDEX(Buildings!$K$7:$K$26,MATCH($A8,Buildings!$A$7:$A$26,0))) -> 201.6 | E8: =Assumptions!$B$13 -> 100 | F8: =ROUNDUP(D8/E8,0) -> 3 | G8: =F8*E8 -> 300 | H8: =Assumptions!$B$14 -> 2.5 | I8: =G8/H8 -> 120 | J8: =INDEX(Buildings!$P$7:$P$26,MATCH($A8,Buildings!$A$7:$A$26,0)) -> 40 | K8: =MAX(0,I8-J8) -> 80 | L8: =G8*Assumptions!$B$15 -> 300000 | M8: =K8*Assumptions!$B$18 -> 36000 | N8: =INDEX(Buildings!$M$7:$M$26,MATCH($A8,Buildings!$A$7:$A$26,0))*Assumptions!$B$16 -> 82500 | O8: =INDEX(Buildings!$O$7:$O$26,MATCH($A8,Buildings!$A$7:$A$26,0))*Assumptions!$B$17 -> 201600 | P8: =SUM(L8:O8) -> 620100 | Q8: =P8*Assumptions!$B$19 -> 74412 | R8: =(P8+Q8)*Assumptions!$B$20 -> 138902.4 | S8: =SUM(P8:R8) -> 833414.4 | T8: =INDEX(Energy!$AD$7:$AD$26,MATCH($A8,Energy!$A$7:$A$26,0)) -> 10894.225 | U8: =IF(T8>0,S8/T8,"No saving") -> 76.500564 | V8: =IF(INDEX(Energy!$U$7:$U$26,MATCH($A8,Energy!$A$7:$A$26,0))>0,S8/INDEX(Energy!$U$7:$U$26,MATCH($A8,Energy!$A$7:$A$26,0)),"n.a.") -> 9642.5676
A9: B03 | B9: =INDEX(Buildings!$B$7:$B$26,MATCH($A9,Buildings!$A$7:$A$26,0)) -> Cedar Chemistry Lab | C9: =INDEX(Buildings!$C$7:$C$26,MATCH($A9,Buildings!$A$7:$A$26,0)) -> North | D9: =INDEX(Buildings!$J$7:$J$26,MATCH($A9,Buildings!$A$7:$A$26,0))*(1-INDEX(Buildings!$K$7:$K$26,MATCH($A9,Buildings!$A$7:$A$26,0))) -> 673.2 | E9: =Assumptions!$B$13 -> 100 | F9: =ROUNDUP(D9/E9,0) -> 7 | G9: =F9*E9 -> 700 | H9: =Assumptions!$B$14 -> 2.5 | I9: =G9/H9 -> 280 | J9: =INDEX(Buildings!$P$7:$P$26,MATCH($A9,Buildings!$A$7:$A$26,0)) -> 90 | K9: =MAX(0,I9-J9) -> 190 | L9: =G9*Assumptions!$B$15 -> 700000 | M9: =K9*Assumptions!$B$18 -> 85500 | N9: =INDEX(Buildings!$M$7:$M$26,MATCH($A9,Buildings!$A$7:$A$26,0))*Assumptions!$B$16 -> 165000 | O9: =INDEX(Buildings!$O$7:$O$26,MATCH($A9,Buildings!$A$7:$A$26,0))*Assumptions!$B$17 -> 217600 | P9: =SUM(L9:O9) -> 1168100 | Q9: =P9*Assumptions!$B$19 -> 140172 | R9: =(P9+Q9)*Assumptions!$B$20 -> 261654.4 | S9: =SUM(P9:R9) -> 1569926.4 | T9: =INDEX(Energy!$AD$7:$AD$26,MATCH($A9,Energy!$A$7:$A$26,0)) -> 13257.843 | U9: =IF(T9>0,S9/T9,"No saving") -> 118.41492 | V9: =IF(INDEX(Energy!$U$7:$U$26,MATCH($A9,Energy!$A$7:$A$26,0))>0,S9/INDEX(Energy!$U$7:$U$26,MATCH($A9,Energy!$A$7:$A$26,0)),"n.a.") -> 5821.735
A10: B04 | B10: =INDEX(Buildings!$B$7:$B$26,MATCH($A10,Buildings!$A$7:$A$26,0)) -> Dove Administration | C10: =INDEX(Buildings!$C$7:$C$26,MATCH($A10,Buildings!$A$7:$A$26,0)) -> North | D10: =INDEX(Buildings!$J$7:$J$26,MATCH($A10,Buildings!$A$7:$A$26,0))*(1-INDEX(Buildings!$K$7:$K$26,MATCH($A10,Buildings!$A$7:$A$26,0))) -> 121.68 | E10: =Assumptions!$B$13 -> 100 | F10: =ROUNDUP(D10/E10,0) -> 2 | G10: =F10*E10 -> 200 | H10: =Assumptions!$B$14 -> 2.5 | I10: =G10/H10 -> 80 | J10: =INDEX(Buildings!$P$7:$P$26,MATCH($A10,Buildings!$A$7:$A$26,0)) -> 25 | K10: =MAX(0,I10-J10) -> 55 | L10: =G10*Assumptions!$B$15 -> 200000 | M10: =K10*Assumptions!$B$18 -> 24750 | N10: =INDEX(Buildings!$M$7:$M$26,MATCH($A10,Buildings!$A$7:$A$26,0))*Assumptions!$B$16 -> 44000 | O10: =INDEX(Buildings!$O$7:$O$26,MATCH($A10,Buildings!$A$7:$A$26,0))*Assumptions!$B$17 -> 153600 | P10: =SUM(L10:O10) -> 422350 | Q10: =P10*Assumptions!$B$19 -> 50682 | R10: =(P10+Q10)*Assumptions!$B$20 -> 94606.4 | S10: =SUM(P10:R10) -> 567638.4 | T10: =INDEX(Energy!$AD$7:$AD$26,MATCH($A10,Energy!$A$7:$A$26,0)) -> 5696.6743 | U10: =IF(T10>0,S10/T10,"No saving") -> 99.643822 | V10: =IF(INDEX(Energy!$U$7:$U$26,MATCH($A10,Energy!$A$7:$A$26,0))>0,S10/INDEX(Energy!$U$7:$U$26,MATCH($A10,Energy!$A$7:$A$26,0)),"n.a.") -> 10882.483
A11: B05 | B11: =INDEX(Buildings!$B$7:$B$26,MATCH($A11,Buildings!$A$7:$A$26,0)) -> Elm Residence | C11: =INDEX(Buildings!$C$7:$C$26,MATCH($A11,Buildings!$A$7:$A$26,0)) -> North | D11: =INDEX(Buildings!$J$7:$J$26,MATCH($A11,Buildings!$A$7:$A$26,0))*(1-INDEX(Buildings!$K$7:$K$26,MATCH($A11,Buildings!$A$7:$A$26,0))) -> 367.2 | E11: =Assumptions!$B$13 -> 100 | F11: =ROUNDUP(D11/E11,0) -> 4 | G11: =F11*E11 -> 400 | H11: =Assumptions!$B$14 -> 2.5 | I11: =G11/H11 -> 160 | J11: =INDEX(Buildings!$P$7:$P$26,MATCH($A11,Buildings!$A$7:$A$26,0)) -> 50 | K11: =MAX(0,I11-J11) -> 110 | L11: =G11*Assumptions!$B$15 -> 400000 | M11: =K11*Assumptions!$B$18 -> 49500 | N11: =INDEX(Buildings!$M$7:$M$26,MATCH($A11,Buildings!$A$7:$A$26,0))*Assumptions!$B$16 -> 121000 | O11: =INDEX(Buildings!$O$7:$O$26,MATCH($A11,Buildings!$A$7:$A$26,0))*Assumptions!$B$17 -> 259200 | P11: =SUM(L11:O11) -> 829700 | Q11: =P11*Assumptions!$B$19 -> 99564 | R11: =(P11+Q11)*Assumptions!$B$20 -> 185852.8 | S11: =SUM(P11:R11) -> 1115116.8 | T11: =INDEX(Energy!$AD$7:$AD$26,MATCH($A11,Energy!$A$7:$A$26,0)) -> 13377.484 | U11: =IF(T11>0,S11/T11,"No saving") -> 83.357738 | V11: =IF(INDEX(Energy!$U$7:$U$26,MATCH($A11,Energy!$A$7:$A$26,0))>0,S11/INDEX(Energy!$U$7:$U$26,MATCH($A11,Energy!$A$7:$A$26,0)),"n.a.") -> 6694.4979
A12: B06 | B12: =INDEX(Buildings!$B$7:$B$26,MATCH($A12,Buildings!$A$7:$A$26,0)) -> Fern Engineering | C12: =INDEX(Buildings!$C$7:$C$26,MATCH($A12,Buildings!$A$7:$A$26,0)) -> Central | D12: =INDEX(Buildings!$J$7:$J$26,MATCH($A12,Buildings!$A$7:$A$26,0))*(1-INDEX(Buildings!$K$7:$K$26,MATCH($A12,Buildings!$A$7:$A$26,0))) -> 484.5 | E12: =Assumptions!$B$13 -> 100 | F12: =ROUNDUP(D12/E12,0) -> 5 | G12: =F12*E12 -> 500 | H12: =Assumptions!$B$14 -> 2.5 | I12: =G12/H12 -> 200 | J12: =INDEX(Buildings!$P$7:$P$26,MATCH($A12,Buildings!$A$7:$A$26,0)) -> 55 | K12: =MAX(0,I12-J12) -> 145 | L12: =G12*Assumptions!$B$15 -> 500000 | M12: =K12*Assumptions!$B$18 -> 65250 | N12: =INDEX(Buildings!$M$7:$M$26,MATCH($A12,Buildings!$A$7:$A$26,0))*Assumptions!$B$16 -> 198000 | O12: =INDEX(Buildings!$O$7:$O$26,MATCH($A12,Buildings!$A$7:$A$26,0))*Assumptions!$B$17 -> 364800 | P12: =SUM(L12:O12) -> 1128050 | Q12: =P12*Assumptions!$B$19 -> 135366 | R12: =(P12+Q12)*Assumptions!$B$20 -> 252683.2 | S12: =SUM(P12:R12) -> 1516099.2 | T12: =INDEX(Energy!$AD$7:$AD$26,MATCH($A12,Energy!$A$7:$A$26,0)) -> 30278.995 | U12: =IF(T12>0,S12/T12,"No saving") -> 50.070988 | V12: =IF(INDEX(Energy!$U$7:$U$26,MATCH($A12,Energy!$A$7:$A$26,0))>0,S12/INDEX(Energy!$U$7:$U$26,MATCH($A12,Energy!$A$7:$A$26,0)),"n.a.") -> 6498.7073
A13: B07 | B13: =INDEX(Buildings!$B$7:$B$26,MATCH($A13,Buildings!$A$7:$A$26,0)) -> Grove Humanities | C13: =INDEX(Buildings!$C$7:$C$26,MATCH($A13,Buildings!$A$7:$A$26,0)) -> Central | D13: =INDEX(Buildings!$J$7:$J$26,MATCH($A13,Buildings!$A$7:$A$26,0))*(1-INDEX(Buildings!$K$7:$K$26,MATCH($A13,Buildings!$A$7:$A$26,0))) -> 179.2 | E13: =Assumptions!$B$13 -> 100 | F13: =ROUNDUP(D13/E13,0) -> 2 | G13: =F13*E13 -> 200 | H13: =Assumptions!$B$14 -> 2.5 | I13: =G13/H13 -> 80 | J13: =INDEX(Buildings!$P$7:$P$26,MATCH($A13,Buildings!$A$7:$A$26,0)) -> 40 | K13: =MAX(0,I13-J13) -> 40 | L13: =G13*Assumptions!$B$15 -> 200000 | M13: =K13*Assumptions!$B$18 -> 18000 | N13: =INDEX(Buildings!$M$7:$M$26,MATCH($A13,Buildings!$A$7:$A$26,0))*Assumptions!$B$16 -> 66000 | O13: =INDEX(Buildings!$O$7:$O$26,MATCH($A13,Buildings!$A$7:$A$26,0))*Assumptions!$B$17 -> 179200 | P13: =SUM(L13:O13) -> 463200 | Q13: =P13*Assumptions!$B$19 -> 55584 | R13: =(P13+Q13)*Assumptions!$B$20 -> 103756.8 | S13: =SUM(P13:R13) -> 622540.8 | T13: =INDEX(Energy!$AD$7:$AD$26,MATCH($A13,Energy!$A$7:$A$26,0)) -> 9934.8595 | U13: =IF(T13>0,S13/T13,"No saving") -> 62.662265 | V13: =IF(INDEX(Energy!$U$7:$U$26,MATCH($A13,Energy!$A$7:$A$26,0))>0,S13/INDEX(Energy!$U$7:$U$26,MATCH($A13,Energy!$A$7:$A$26,0)),"n.a.") -> 7895.6658
A14: B08 | B14: =INDEX(Buildings!$B$7:$B$26,MATCH($A14,Buildings!$A$7:$A$26,0)) -> Hazel Sports Centre | C14: =INDEX(Buildings!$C$7:$C$26,MATCH($A14,Buildings!$A$7:$A$26,0)) -> Central | D14: =INDEX(Buildings!$J$7:$J$26,MATCH($A14,Buildings!$A$7:$A$26,0))*(1-INDEX(Buildings!$K$7:$K$26,MATCH($A14,Buildings!$A$7:$A$26,0))) -> 643.5 | E14: =Assumptions!$B$13 -> 100 | F14: =ROUNDUP(D14/E14,0) -> 7 | G14: =F14*E14 -> 700 | H14: =Assumptions!$B$14 -> 2.5 | I14: =G14/H14 -> 280 | J14: =INDEX(Buildings!$P$7:$P$26,MATCH($A14,Buildings!$A$7:$A$26,0)) -> 90 | K14: =MAX(0,I14-J14) -> 190 | L14: =G14*Assumptions!$B$15 -> 700000 | M14: =K14*Assumptions!$B$18 -> 85500 | N14: =INDEX(Buildings!$M$7:$M$26,MATCH($A14,Buildings!$A$7:$A$26,0))*Assumptions!$B$16 -> 154000 | O14: =INDEX(Buildings!$O$7:$O$26,MATCH($A14,Buildings!$A$7:$A$26,0))*Assumptions!$B$17 -> 208000 | P14: =SUM(L14:O14) -> 1147500 | Q14: =P14*Assumptions!$B$19 -> 137700 | R14: =(P14+Q14)*Assumptions!$B$20 -> 257040 | S14: =SUM(P14:R14) -> 1542240 | T14: =INDEX(Energy!$AD$7:$AD$26,MATCH($A14,Energy!$A$7:$A$26,0)) -> 10483.229 | U14: =IF(T14>0,S14/T14,"No saving") -> 147.11498 | V14: =IF(INDEX(Energy!$U$7:$U$26,MATCH($A14,Energy!$A$7:$A$26,0))>0,S14/INDEX(Energy!$U$7:$U$26,MATCH($A14,Energy!$A$7:$A$26,0)),"n.a.") -> 5526.0981
A15: B09 | B15: =INDEX(Buildings!$B$7:$B$26,MATCH($A15,Buildings!$A$7:$A$26,0)) -> Iris Computing | C15: =INDEX(Buildings!$C$7:$C$26,MATCH($A15,Buildings!$A$7:$A$26,0)) -> Central | D15: =INDEX(Buildings!$J$7:$J$26,MATCH($A15,Buildings!$A$7:$A$26,0))*(1-INDEX(Buildings!$K$7:$K$26,MATCH($A15,Buildings!$A$7:$A$26,0))) -> 243.36 | E15: =Assumptions!$B$13 -> 100 | F15: =ROUNDUP(D15/E15,0) -> 3 | G15: =F15*E15 -> 300 | H15: =Assumptions!$B$14 -> 2.5 | I15: =G15/H15 -> 120 | J15: =INDEX(Buildings!$P$7:$P$26,MATCH($A15,Buildings!$A$7:$A$26,0)) -> 25 | K15: =MAX(0,I15-J15) -> 95 | L15: =G15*Assumptions!$B$15 -> 300000 | M15: =K15*Assumptions!$B$18 -> 42750 | N15: =INDEX(Buildings!$M$7:$M$26,MATCH($A15,Buildings!$A$7:$A$26,0))*Assumptions!$B$16 -> 132000 | O15: =INDEX(Buildings!$O$7:$O$26,MATCH($A15,Buildings!$A$7:$A$26,0))*Assumptions!$B$17 -> 307200 | P15: =SUM(L15:O15) -> 781950 | Q15: =P15*Assumptions!$B$19 -> 93834 | R15: =(P15+Q15)*Assumptions!$B$20 -> 175156.8 | S15: =SUM(P15:R15) -> 1050940.8 | T15: =INDEX(Energy!$AD$7:$AD$26,MATCH($A15,Energy!$A$7:$A$26,0)) -> 17771.074 | U15: =IF(T15>0,S15/T15,"No saving") -> 59.137719 | V15: =IF(INDEX(Energy!$U$7:$U$26,MATCH($A15,Energy!$A$7:$A$26,0))>0,S15/INDEX(Energy!$U$7:$U$26,MATCH($A15,Energy!$A$7:$A$26,0)),"n.a.") -> 13002.319
A16: B10 | B16: =INDEX(Buildings!$B$7:$B$26,MATCH($A16,Buildings!$A$7:$A$26,0)) -> Juniper Research | C16: =INDEX(Buildings!$C$7:$C$26,MATCH($A16,Buildings!$A$7:$A$26,0)) -> Central | D16: =INDEX(Buildings!$J$7:$J$26,MATCH($A16,Buildings!$A$7:$A$26,0))*(1-INDEX(Buildings!$K$7:$K$26,MATCH($A16,Buildings!$A$7:$A$26,0))) -> 489.6 | E16: =Assumptions!$B$13 -> 100 | F16: =ROUNDUP(D16/E16,0) -> 5 | G16: =F16*E16 -> 500 | H16: =Assumptions!$B$14 -> 2.5 | I16: =G16/H16 -> 200 | J16: =INDEX(Buildings!$P$7:$P$26,MATCH($A16,Buildings!$A$7:$A$26,0)) -> 50 | K16: =MAX(0,I16-J16) -> 150 | L16: =G16*Assumptions!$B$15 -> 500000 | M16: =K16*Assumptions!$B$18 -> 67500 | N16: =INDEX(Buildings!$M$7:$M$26,MATCH($A16,Buildings!$A$7:$A$26,0))*Assumptions!$B$16 -> 187000 | O16: =INDEX(Buildings!$O$7:$O$26,MATCH($A16,Buildings!$A$7:$A$26,0))*Assumptions!$B$17 -> 345600 | P16: =SUM(L16:O16) -> 1100100 | Q16: =P16*Assumptions!$B$19 -> 132012 | R16: =(P16+Q16)*Assumptions!$B$20 -> 246422.4 | S16: =SUM(P16:R16) -> 1478534.4 | T16: =INDEX(Energy!$AD$7:$AD$26,MATCH($A16,Energy!$A$7:$A$26,0)) -> 22232.888 | U16: =IF(T16>0,S16/T16,"No saving") -> 66.50213 | V16: =IF(INDEX(Energy!$U$7:$U$26,MATCH($A16,Energy!$A$7:$A$26,0))>0,S16/INDEX(Energy!$U$7:$U$26,MATCH($A16,Energy!$A$7:$A$26,0)),"n.a.") -> 6168.6822
A17: B11 | B17: =INDEX(Buildings!$B$7:$B$26,MATCH($A17,Buildings!$A$7:$A$26,0)) -> Kingfisher Hall | C17: =INDEX(Buildings!$C$7:$C$26,MATCH($A17,Buildings!$A$7:$A$26,0)) -> South | D17: =INDEX(Buildings!$J$7:$J$26,MATCH($A17,Buildings!$A$7:$A$26,0))*(1-INDEX(Buildings!$K$7:$K$26,MATCH($A17,Buildings!$A$7:$A$26,0))) -> 249.05 | E17: =Assumptions!$B$13 -> 100 | F17: =ROUNDUP(D17/E17,0) -> 3 | G17: =F17*E17 -> 300 | H17: =Assumptions!$B$14 -> 2.5 | I17: =G17/H17 -> 120 | J17: =INDEX(Buildings!$P$7:$P$26,MATCH($A17,Buildings!$A$7:$A$26,0)) -> 55 | K17: =MAX(0,I17-J17) -> 65 | L17: =G17*Assumptions!$B$15 -> 300000 | M17: =K17*Assumptions!$B$18 -> 29250 | N17: =INDEX(Buildings!$M$7:$M$26,MATCH($A17,Buildings!$A$7:$A$26,0))*Assumptions!$B$16 -> 93500 | O17: =INDEX(Buildings!$O$7:$O$26,MATCH($A17,Buildings!$A$7:$A$26,0))*Assumptions!$B$17 -> 187200 | P17: =SUM(L17:O17) -> 609950 | Q17: =P17*Assumptions!$B$19 -> 73194 | R17: =(P17+Q17)*Assumptions!$B$20 -> 136628.8 | S17: =SUM(P17:R17) -> 819772.8 | T17: =INDEX(Energy!$AD$7:$AD$26,MATCH($A17,Energy!$A$7:$A$26,0)) -> 13740.154 | U17: =IF(T17>0,S17/T17,"No saving") -> 59.662562 | V17: =IF(INDEX(Energy!$U$7:$U$26,MATCH($A17,Energy!$A$7:$A$26,0))>0,S17/INDEX(Energy!$U$7:$U$26,MATCH($A17,Energy!$A$7:$A$26,0)),"n.a.") -> 6335.039
A18: B12 | B18: =INDEX(Buildings!$B$7:$B$26,MATCH($A18,Buildings!$A$7:$A$26,0)) -> Larch Medical Sciences | C18: =INDEX(Buildings!$C$7:$C$26,MATCH($A18,Buildings!$A$7:$A$26,0)) -> South | D18: =INDEX(Buildings!$J$7:$J$26,MATCH($A18,Buildings!$A$7:$A$26,0))*(1-INDEX(Buildings!$K$7:$K$26,MATCH($A18,Buildings!$A$7:$A$26,0))) -> 476 | E18: =Assumptions!$B$13 -> 100 | F18: =ROUNDUP(D18/E18,0) -> 5 | G18: =F18*E18 -> 500 | H18: =Assumptions!$B$14 -> 2.5 | I18: =G18/H18 -> 200 | J18: =INDEX(Buildings!$P$7:$P$26,MATCH($A18,Buildings!$A$7:$A$26,0)) -> 40 | K18: =MAX(0,I18-J18) -> 160 | L18: =G18*Assumptions!$B$15 -> 500000 | M18: =K18*Assumptions!$B$18 -> 72000 | N18: =INDEX(Buildings!$M$7:$M$26,MATCH($A18,Buildings!$A$7:$A$26,0))*Assumptions!$B$16 -> 220000 | O18: =INDEX(Buildings!$O$7:$O$26,MATCH($A18,Buildings!$A$7:$A$26,0))*Assumptions!$B$17 -> 476000 | P18: =SUM(L18:O18) -> 1268000 | Q18: =P18*Assumptions!$B$19 -> 152160 | R18: =(P18+Q18)*Assumptions!$B$20 -> 284032 | S18: =SUM(P18:R18) -> 1704192 | T18: =INDEX(Energy!$AD$7:$AD$26,MATCH($A18,Energy!$A$7:$A$26,0)) -> 36747.084 | U18: =IF(T18>0,S18/T18,"No saving") -> 46.376251 | V18: =IF(INDEX(Energy!$U$7:$U$26,MATCH($A18,Energy!$A$7:$A$26,0))>0,S18/INDEX(Energy!$U$7:$U$26,MATCH($A18,Energy!$A$7:$A$26,0)),"n.a.") -> 5035.315
... A26: B20 | B26: =INDEX(Buildings!$B$7:$B$26,MATCH($A26,Buildings!$A$7:$A$26,0)) -> Willow Innovation | C26: =INDEX(Buildings!$C$7:$C$26,MATCH($A26,Buildings!$A$7:$A$26,0)) -> West | D26: =INDEX(Buildings!$J$7:$J$26,MATCH($A26,Buildings!$A$7:$A$26,0))*(1-INDEX(Buildings!$K$7:$K$26,MATCH($A26,Buildings!$A$7:$A$26,0))) -> 435.2 | E26: =Assumptions!$B$13 -> 100 | F26: =ROUNDUP(D26/E26,0) -> 5 | G26: =F26*E26 -> 500 | H26: =Assumptions!$B$14 -> 2.5 | I26: =G26/H26 -> 200 | J26: =INDEX(Buildings!$P$7:$P$26,MATCH($A26,Buildings!$A$7:$A$26,0)) -> 50 | K26: =MAX(0,I26-J26) -> 150 | L26: =G26*Assumptions!$B$15 -> 500000 | M26: =K26*Assumptions!$B$18 -> 67500 | N26: =INDEX(Buildings!$M$7:$M$26,MATCH($A26,Buildings!$A$7:$A$26,0))*Assumptions!$B$16 -> 170500 | O26: =INDEX(Buildings!$O$7:$O$26,MATCH($A26,Buildings!$A$7:$A$26,0))*Assumptions!$B$17 -> 307200 | P26: =SUM(L26:O26) -> 1045200 | Q26: =P26*Assumptions!$B$19 -> 125424 | R26: =(P26+Q26)*Assumptions!$B$20 -> 234124.8 | S26: =SUM(P26:R26) -> 1404748.8 | T26: =INDEX(Energy!$AD$7:$AD$26,MATCH($A26,Energy!$A$7:$A$26,0)) -> 20573.844 | U26: =IF(T26>0,S26/T26,"No saving") -> 68.278384 | V26: =IF(INDEX(Energy!$U$7:$U$26,MATCH($A26,Energy!$A$7:$A$26,0))>0,S26/INDEX(Energy!$U$7:$U$26,MATCH($A26,Energy!$A$7:$A$26,0)),"n.a.") -> 9014.6091
B28: Portfolio total | D28: =SUM(D7:D26) -> 6881.77 | F28: =SUM(F7:F26) -> 78 | G28: =SUM(G7:G26) -> 7800 | I28: =SUM(I7:I26) -> 3120 | J28: =SUM(J7:J26) -> 1040 | K28: =SUM(K7:K26) -> 2080 | L28: =SUM(L7:L26) -> 7800000 | M28: =SUM(M7:M26) -> 936000 | N28: =SUM(N7:N26) -> 2486000 | O28: =SUM(O7:O26) -> 5078400 | P28: =SUM(P7:P26) -> 16300400 | ... T28: =SUM(T7:T26) -> 323603.16 | U28: =IF(T28>0,S28/T28,"No saving") -> 67.699393 | V28: =S28/Energy!U28 -> 6962.2439

Sheet Consultant
A2: Standardised consultant tariff comparison
A4: Invented consultant rates. Identical modelled kWh under both price sets isolates tariff effects. Energy bills only, excluding maintenance.
A6: Building ID | B6: Fictional consultant | C6: Gas p/kWh | D6: Electricity p/kWh | E6: Baseline gas kWh | F6: Baseline electricity kWh | G6: Post grid kWh | H6: Own-rate baseline £ | I6: Own-rate post £ | J6: Own-rate bill saving £ | K6: Common baseline £ | L6: Common post £ | M6: Common bill saving £ | N6: Baseline repricing £ | O6: Post repricing £ | P6: Saving adjustment £ | Q6: Bridge residual £
A7: B01 | B7: Atlas Demo | C7: 4.2 | D7: 19.5 | E7: =INDEX(Energy!$D$7:$D$26,MATCH($A7,Energy!$A$7:$A$26,0)) -> 620000 | F7: =INDEX(Energy!$E$7:$E$26,MATCH($A7,Energy!$A$7:$A$26,0)) -> 490000 | G7: =INDEX(Energy!$P$7:$P$26,MATCH($A7,Energy!$A$7:$A$26,0)) -> 551529.7 | H7: =(E7*C7+F7*D7)/100 -> 121590 | I7: =G7*D7/100 -> 107548.29 | J7: =H7-I7 -> 14041.709 | K7: =INDEX(Energy!$W$7:$W$26,MATCH($A7,Energy!$A$7:$A$26,0)) -> 152835 | L7: =INDEX(Energy!$X$7:$X$26,MATCH($A7,Energy!$A$7:$A$26,0)) -> 135179.93 | M7: =K7-L7 -> 17655.071 | N7: =K7-H7 -> 31245 | O7: =L7-I7 -> 27631.638 | P7: =M7-J7 -> 3613.3622 | Q7: =P7-(N7-O7) -> 0
A8: B02 | B8: Atlas Demo | C8: 4.2 | D8: 19.5 | E8: =INDEX(Energy!$D$7:$D$26,MATCH($A8,Energy!$A$7:$A$26,0)) -> 510000 | F8: =INDEX(Energy!$E$7:$E$26,MATCH($A8,Energy!$A$7:$A$26,0)) -> 320000 | G8: =INDEX(Energy!$P$7:$P$26,MATCH($A8,Energy!$A$7:$A$26,0)) -> 369995 | H8: =(E8*C8+F8*D8)/100 -> 83820 | I8: =G8*D8/100 -> 72149.025 | J8: =H8-I8 -> 11670.975 | K8: =INDEX(Energy!$W$7:$W$26,MATCH($A8,Energy!$A$7:$A$26,0)) -> 105360 | L8: =INDEX(Energy!$X$7:$X$26,MATCH($A8,Energy!$A$7:$A$26,0)) -> 90685.775 | M8: =K8-L8 -> 14674.225 | N8: =K8-H8 -> 21540 | O8: =L8-I8 -> 18536.75 | P8: =M8-J8 -> 3003.2505 | Q8: =P8-(N8-O8) -> 0
A9: B03 | B9: Atlas Demo | C9: 4.2 | D9: 19.5 | E9: =INDEX(Energy!$D$7:$D$26,MATCH($A9,Energy!$A$7:$A$26,0)) -> 1680000 | F9: =INDEX(Energy!$E$7:$E$26,MATCH($A9,Energy!$A$7:$A$26,0)) -> 2840000 | G9: =INDEX(Energy!$P$7:$P$26,MATCH($A9,Energy!$A$7:$A$26,0)) -> 3119584.5 | H9: =(E9*C9+F9*D9)/100 -> 624360 | I9: =G9*D9/100 -> 608318.97 | J9: =H9-I9 -> 16041.026 | K9: =INDEX(Energy!$W$7:$W$26,MATCH($A9,Energy!$A$7:$A$26,0)) -> 784788 | L9: =INDEX(Energy!$X$7:$X$26,MATCH($A9,Energy!$A$7:$A$26,0)) -> 764610.16 | M9: =K9-L9 -> 20177.843 | N9: =K9-H9 -> 160428 | O9: =L9-I9 -> 156291.18 | P9: =M9-J9 -> 4136.8174 | Q9: =P9-(N9-O9) -> 0
A10: B04 | B10: Atlas Demo | C10: 4.2 | D10: 19.5 | E10: =INDEX(Energy!$D$7:$D$26,MATCH($A10,Energy!$A$7:$A$26,0)) -> 310000 | F10: =INDEX(Energy!$E$7:$E$26,MATCH($A10,Energy!$A$7:$A$26,0)) -> 210000 | G10: =INDEX(Energy!$P$7:$P$26,MATCH($A10,Energy!$A$7:$A$26,0)) -> 243257.14 | H10: =(E10*C10+F10*D10)/100 -> 53970 | I10: =G10*D10/100 -> 47435.143 | J10: =H10-I10 -> 6534.8571 | K10: =INDEX(Energy!$W$7:$W$26,MATCH($A10,Energy!$A$7:$A$26,0)) -> 67839 | L10: =INDEX(Energy!$X$7:$X$26,MATCH($A10,Energy!$A$7:$A$26,0)) -> 59622.326 | M10: =K10-L10 -> 8216.6743 | N10: =K10-H10 -> 13869 | O10: =L10-I10 -> 12187.183 | P10: =M10-J10 -> 1681.8171 | Q10: =P10-(N10-O10) -> 0
A11: B05 | B11: Atlas Demo | C11: 4.2 | D11: 19.5 | E11: =INDEX(Energy!$D$7:$D$26,MATCH($A11,Energy!$A$7:$A$26,0)) -> 1020000 | F11: =INDEX(Energy!$E$7:$E$26,MATCH($A11,Energy!$A$7:$A$26,0)) -> 460000 | G11: =INDEX(Energy!$P$7:$P$26,MATCH($A11,Energy!$A$7:$A$26,0)) -> 608015.16 | H11: =(E11*C11+F11*D11)/100 -> 132540 | I11: =G11*D11/100 -> 118562.96 | J11: =H11-I11 -> 13977.044 | K11: =INDEX(Energy!$W$7:$W$26,MATCH($A11,Energy!$A$7:$A$26,0)) -> 166602 | L11: =INDEX(Energy!$X$7:$X$26,MATCH($A11,Energy!$A$7:$A$26,0)) -> 149024.52 | M11: =K11-L11 -> 17577.484 | N11: =K11-H11 -> 34062 | O11: =L11-I11 -> 30461.56 | P11: =M11-J11 -> 3600.4404 | Q11: =P11-(N11-O11) -> 0
A12: B06 | B12: Beacon Demo | C12: 6.1 | D12: 31 | E12: =INDEX(Energy!$D$7:$D$26,MATCH($A12,Energy!$A$7:$A$26,0)) -> 1390000 | F12: =INDEX(Energy!$E$7:$E$26,MATCH($A12,Energy!$A$7:$A$26,0)) -> 1530000 | G12: =INDEX(Energy!$P$7:$P$26,MATCH($A12,Energy!$A$7:$A$26,0)) -> 1683623 | H12: =(E12*C12+F12*D12)/100 -> 559090 | I12: =G12*D12/100 -> 521923.14 | J12: =H12-I12 -> 37166.861 | K12: =INDEX(Energy!$W$7:$W$26,MATCH($A12,Energy!$A$7:$A$26,0)) -> 448395 | L12: =INDEX(Energy!$X$7:$X$26,MATCH($A12,Energy!$A$7:$A$26,0)) -> 412656 | M12: =K12-L12 -> 35738.995 | N12: =K12-H12 -> -110695 | O12: =L12-I12 -> -109267.13 | P12: =M12-J12 -> -1427.8653 | Q12: =P12-(N12-O12) -> 0
A13: B07 | B13: Beacon Demo | C13: 6.1 | D13: 31 | E13: =INDEX(Energy!$D$7:$D$26,MATCH($A13,Energy!$A$7:$A$26,0)) -> 470000 | F13: =INDEX(Energy!$E$7:$E$26,MATCH($A13,Energy!$A$7:$A$26,0)) -> 260000 | G13: =INDEX(Energy!$P$7:$P$26,MATCH($A13,Energy!$A$7:$A$26,0)) -> 312228.24 | H13: =(E13*C13+F13*D13)/100 -> 109270 | I13: =G13*D13/100 -> 96790.753 | J13: =H13-I13 -> 12479.247 | K13: =INDEX(Energy!$W$7:$W$26,MATCH($A13,Energy!$A$7:$A$26,0)) -> 88542 | L13: =INDEX(Energy!$X$7:$X$26,MATCH($A13,Energy!$A$7:$A$26,0)) -> 76527.14 | M13: =K13-L13 -> 12014.86 | N13: =K13-H13 -> -20728 | O13: =L13-I13 -> -20263.612 | P13: =M13-J13 -> -464.38753 | Q13: =P13-(N13-O13) -> 0
A14: B08 | B14: Beacon Demo | C14: 6.1 | D14: 31 | E14: =INDEX(Energy!$D$7:$D$26,MATCH($A14,Energy!$A$7:$A$26,0)) -> 1750000 | F14: =INDEX(Energy!$E$7:$E$26,MATCH($A14,Energy!$A$7:$A$26,0)) -> 860000 | G14: =INDEX(Energy!$P$7:$P$26,MATCH($A14,Energy!$A$7:$A$26,0)) -> 1165127.6 | H14: =(E14*C14+F14*D14)/100 -> 373350 | I14: =G14*D14/100 -> 361189.55 | J14: =H14-I14 -> 12160.448 | K14: =INDEX(Energy!$W$7:$W$26,MATCH($A14,Energy!$A$7:$A$26,0)) -> 303186 | L14: =INDEX(Energy!$X$7:$X$26,MATCH($A14,Energy!$A$7:$A$26,0)) -> 285572.77 | M14: =K14-L14 -> 17613.229 | N14: =K14-H14 -> -70164 | O14: =L14-I14 -> -75616.78 | P14: =M14-J14 -> 5452.7803 | Q14: =P14-(N14-O14) -> 0
A15: B09 | B15: Beacon Demo | C15: 6.1 | D15: 31 | E15: =INDEX(Energy!$D$7:$D$26,MATCH($A15,Energy!$A$7:$A$26,0)) -> 450000 | F15: =INDEX(Energy!$E$7:$E$26,MATCH($A15,Energy!$A$7:$A$26,0)) -> 2380000 | G15: =INDEX(Energy!$P$7:$P$26,MATCH($A15,Energy!$A$7:$A$26,0)) -> 2389257.1 | H15: =(E15*C15+F15*D15)/100 -> 765250 | I15: =G15*D15/100 -> 740669.71 | J15: =H15-I15 -> 24580.286 | K15: =INDEX(Energy!$W$7:$W$26,MATCH($A15,Energy!$A$7:$A$26,0)) -> 607098 | L15: =INDEX(Energy!$X$7:$X$26,MATCH($A15,Energy!$A$7:$A$26,0)) -> 585606.93 | M15: =K15-L15 -> 21491.074 | N15: =K15-H15 -> -158152 | O15: =L15-I15 -> -155062.79 | P15: =M15-J15 -> -3089.2114 | Q15: =P15-(N15-O15) -> 0
A16: B10 | B16: Beacon Demo | C16: 6.1 | D16: 31 | E16: =INDEX(Energy!$D$7:$D$26,MATCH($A16,Energy!$A$7:$A$26,0)) -> 1460000 | F16: =INDEX(Energy!$E$7:$E$26,MATCH($A16,Energy!$A$7:$A$26,0)) -> 2490000 | G16: =INDEX(Energy!$P$7:$P$26,MATCH($A16,Energy!$A$7:$A$26,0)) -> 2692264.8 | H16: =(E16*C16+F16*D16)/100 -> 860960 | I16: =G16*D16/100 -> 834602.1 | J16: =H16-I16 -> 26357.9 | K16: =INDEX(Energy!$W$7:$W$26,MATCH($A16,Energy!$A$7:$A$26,0)) -> 687387 | L16: =INDEX(Energy!$X$7:$X$26,MATCH($A16,Energy!$A$7:$A$26,0)) -> 659874.11 | M16: =K16-L16 -> 27512.888 | N16: =K16-H16 -> -173573 | O16: =L16-I16 -> -174727.99 | P16: =M16-J16 -> 1154.988 | Q16: =P16-(N16-O16) -> 0
A17: B11 | B17: Campus Demo | C17: 5.8 | D17: 27.5 | E17: =INDEX(Energy!$D$7:$D$26,MATCH($A17,Energy!$A$7:$A$26,0)) -> 780000 | F17: =INDEX(Energy!$E$7:$E$26,MATCH($A17,Energy!$A$7:$A$26,0)) -> 350000 | G17: =INDEX(Energy!$P$7:$P$26,MATCH($A17,Energy!$A$7:$A$26,0)) -> 447730.91 | H17: =(E17*C17+F17*D17)/100 -> 141490 | I17: =G17*D17/100 -> 123126 | J17: =H17-I17 -> 18364 | K17: =INDEX(Energy!$W$7:$W$26,MATCH($A17,Energy!$A$7:$A$26,0)) -> 126969 | L17: =INDEX(Energy!$X$7:$X$26,MATCH($A17,Energy!$A$7:$A$26,0)) -> 109738.85 | M17: =K17-L17 -> 17230.154 | N17: =K17-H17 -> -14521 | O17: =L17-I17 -> -13387.154 | P17: =M17-J17 -> -1133.8458 | Q17: =P17-(N17-O17) -> 0
A18: B12 | B18: Campus Demo | C18: 5.8 | D18: 27.5 | E18: =INDEX(Energy!$D$7:$D$26,MATCH($A18,Energy!$A$7:$A$26,0)) -> 2050000 | F18: =INDEX(Energy!$E$7:$E$26,MATCH($A18,Energy!$A$7:$A$26,0)) -> 3620000 | G18: =INDEX(Energy!$P$7:$P$26,MATCH($A18,Energy!$A$7:$A$26,0)) -> 3889452.9 | H18: =(E18*C18+F18*D18)/100 -> 1114400 | I18: =G18*D18/100 -> 1069599.6 | J18: =H18-I18 -> 44800.441 | K18: =INDEX(Energy!$W$7:$W$26,MATCH($A18,Energy!$A$7:$A$26,0)) -> 995502 | L18: =INDEX(Energy!$X$7:$X$26,MATCH($A18,Energy!$A$7:$A$26,0)) -> 953304.92 | M18: =K18-L18 -> 42197.084 | N18: =K18-H18 -> -118898 | O18: =L18-I18 -> -116294.64 | P18: =M18-J18 -> -2603.3571 | Q18: =P18-(N18-O18) -> 0
... A26: B20 | B26: Delta Demo | C26: 4.8 | D26: 22 | E26: =INDEX(Energy!$D$7:$D$26,MATCH($A26,Energy!$A$7:$A$26,0)) -> 920000 | F26: =INDEX(Energy!$E$7:$E$26,MATCH($A26,Energy!$A$7:$A$26,0)) -> 1660000 | G26: =INDEX(Energy!$P$7:$P$26,MATCH($A26,Energy!$A$7:$A$26,0)) -> 1750828.9 | H26: =(E26*C26+F26*D26)/100 -> 409360 | I26: =G26*D26/100 -> 385182.35 | J26: =H26-I26 -> 24177.648 | K26: =INDEX(Energy!$W$7:$W$26,MATCH($A26,Energy!$A$7:$A$26,0)) -> 455442 | L26: =INDEX(Energy!$X$7:$X$26,MATCH($A26,Energy!$A$7:$A$26,0)) -> 429128.16 | M26: =K26-L26 -> 26313.844 | N26: =K26-H26 -> 46082 | O26: =L26-I26 -> 43945.805 | P26: =M26-J26 -> 2136.1953 | Q26: =P26-(N26-O26) -> 0
B28: Portfolio total | E28: =SUM(E7:E26) -> 19000000 | F28: =SUM(F7:F26) -> 23200000 | G28: =SUM(G7:G26) -> 25622427 | H28: =SUM(H7:H26) -> 6969070 | I28: =SUM(I7:I26) -> 6578771.1 | J28: =SUM(J7:J26) -> 390298.87 | K28: =SUM(K7:K26) -> 6689520 | L28: =SUM(L7:L26) -> 6280056.8 | ... Q28: =SUM(Q7:Q26) -> 0

Sheet Buildings
A2: Fictional building register
A4: Amber cells are editable. All buildings, surveys, capacities and study references are invented training data.
